<?xml version="1.0" encoding="utf-8"?>
<robot name="pai_robot">

	<link name="base_footprint" />

	<joint name="fixed" type="fixed">
		<parent link="base_footprint" />
		<child link="base_link" />
	</joint>

	<link name="base_link">
		<inertial>
			<origin xyz="0.00242324 -5.699E-05 0.04030078" rpy="0 0 0" />
			<mass value="2.1609" />
			<inertia ixx="0.00900968" ixy="-2.533E-05" ixz="-0.00013112" iyy="0.00978166" iyz="2E-07" izz="0.00416554" />
		</inertial>
		<visual>
			<origin xyz="0 0 0" rpy="0 0 0" />
			<geometry>
				<!-- <box size="0.1 0.1 0.1" /> -->
				<mesh filename="package://pi_12dof_release_v1/meshes/baselink_1.STL" />
			</geometry>
			<material name="">
				<color rgba="1 1 1 1" />
			</material>
		</visual>
		<collision>
			<origin xyz="0 0 0.08" rpy="0 0 0" />
			<geometry>
				<box size="0.1 0.1 0.1" />
				<!-- <mesh filename="package://pi_12dof_release_v1/meshes/baselink_1.STL" /> -->
			</geometry>
		</collision>
	</link>

<!-- left leg -->
	<link name="l_hip_pitch_link">
		<inertial>
			<origin xyz="0.00086268 0.05441908 -0.00025859" rpy="0 0 0" />
			<mass value="0.38968624" />
			<inertia ixx="0.00010076" ixy="-4.2E-07" ixz="-4E-08" iyy="0.00010507" iyz="-3E-07" izz="0.00012834" />
		</inertial>
		<visual>
			<origin xyz="0 0 0" rpy="0 0 0" />
			<geometry>
				<mesh filename="package://pi_12dof_release_v1/meshes/l_hip_pitch_link.STL" />
			</geometry>
			<material name="">
				<color rgba="0.75294 0.75294 0.75294 1" />
			</material>
		</visual>
		<collision>
			<origin xyz="0 0 0" rpy="0 0 0" />
			<geometry>
				<!-- <box size="0.001 0.001 0.001" /> -->
				<mesh filename="package://pi_12dof_release_v1/meshes/l_hip_pitch_link.STL" />
			</geometry>
		</collision>
	</link>
	<joint name="l_hip_pitch_joint" type="revolute">
		<origin xyz="-5.1979E-05 0.0233 -0.033" rpy="0 -0.25 0" />
		<parent link="base_link" />
		<child link="l_hip_pitch_link" />
		<axis xyz="0 1 0" />
		<limit lower="-1.25" upper="1.75" effort="21" velocity="21" />
	</joint>
	<link name="l_hip_roll_link">
		<inertial>
			<origin xyz="-0.00207707 0.00026598 -0.0608194" rpy="0 0 0" />
			<mass value="0.38851552" />
			<inertia ixx="0.00027068" ixy="-7.6E-07" ixz="3.136E-05" iyy="0.0003332" iyz="8.8E-07" izz="0.00013543" />
		</inertial>
		<visual>
			<origin xyz="0 0 0" rpy="0 0 0" />
			<geometry>
				<mesh filename="package://pi_12dof_release_v1/meshes/l_hip_roll_link.STL" />
			</geometry>
			<material name="">
				<color rgba="0.75294 0.75294 0.75294 1" />
			</material>
		</visual>
		<collision>
			<origin xyz="0 0 0" rpy="0 0 0" />
			<geometry>
				<!-- <box size="0.001 0.001 0.001" /> -->
				<mesh filename="package://pi_12dof_release_v1/meshes/l_hip_roll_link.STL" />
			</geometry>
		</collision>
	</link>
	<joint name="l_hip_roll_joint" type="revolute">
		<origin xyz="0 0.0568 0" rpy="0 0 0" />
		<parent link="l_hip_pitch_link" />
		<child link="l_hip_roll_link" />
		<axis xyz="1 0 0" />
		<limit lower="-0.12" upper="0.5" effort="21" velocity="21" />
	</joint>
	<link name="l_hip_yaw_link">
		<inertial>
			<origin xyz="0 -0.00115822 -0.04755896" rpy="0 0 0" />
			<mass value="0.11270879" />
			<inertia ixx="0.00012497" ixy="0" ixz="0" iyy="5.82E-05" iyz="-3.21E-06" izz="9.438E-05" />
		</inertial>
		<visual>
			<origin xyz="0 0 0" rpy="0 0 0" />
			<geometry>
				<mesh filename="package://pi_12dof_release_v1/meshes/l_thigh_link.STL" />
			</geometry>
			<material name="">
				<color rgba="0.75294 0.75294 0.75294 1" />
			</material>
		</visual>
		<collision>
			<origin xyz="0 0 0" rpy="0 0 0" />
			<geometry>
				<!-- <box size="0.001 0.001 0.001" /> -->
				<mesh filename="package://pi_12dof_release_v1/meshes/l_thigh_link.STL" />
			</geometry>
		</collision>
	</link>
	<joint name="l_hip_yaw_joint" type="revolute">
		<origin xyz="0 0 -0.06925" rpy="0 0 0" />
		<parent link="l_hip_roll_link" />
		<child link="l_hip_yaw_link" />
		<axis xyz="0 0 1" />
		<limit lower="-0.3" upper="0.6" effort="21" velocity="21" />
	</joint>
	<link name="l_knee_pitch_link">
		<inertial>
			<origin xyz="0.00026627 0.00386537 -0.06971210" rpy="0 0 0" />
			<mass value="0.81374212" />
			<inertia ixx="0.00352123" ixy="0.00000020" ixz="0.00000072" iyy="0.00349946" iyz="0.00002072" izz="0.00017468" />
		</inertial>
		<visual>
			<origin xyz="0 0 0" rpy="0 0 0" />
			<geometry>
				<mesh filename="package://pi_12dof_release_v1/meshes/l_calf_link.STL" />
			</geometry>
			<material name="">
				<color rgba="0.75294 0.75294 0.75294 1" />
			</material>
		</visual>
		<collision>
			<origin xyz="0 0 0" rpy="0 0 0" />
			<geometry>
				<!-- <box size="0.001 0.001 0.001" /> -->
				<mesh filename="package://pi_12dof_release_v1/meshes/l_calf_link.STL" />
			</geometry>
		</collision>
	</link>
	<joint name="l_knee_pitch_joint" type="revolute">
		<origin xyz="0 0 -0.07025" rpy="0 0.65 0" />
		<parent link="l_hip_yaw_link" />
		<child link="l_knee_pitch_link" />
		<axis xyz="0 1 0" />
		<limit lower="-0.65" upper="1.65" effort="21" velocity="21" />
	</joint>
	<link name="l_ankle_pitch_link">
		<inertial>
			<origin xyz="0.00467932 -0.00077699 0" rpy="0 0 0" />
			<mass value="0.1759244" />
			<inertia ixx="0.00011981" ixy="-6.4E-07" ixz="0" iyy="0.00022179" iyz="0" izz="0.00030766" />
		</inertial>
		<visual>
			<origin xyz="0 0 0" rpy="0 0 0" />
			<geometry>
				<mesh filename="package://pi_12dof_release_v1/meshes/l_ankle_pitch_link.STL" />
			</geometry>
			<material name="">
				<color rgba="0.75294 0.75294 0.75294 1" />
			</material>
		</visual>
		<collision>
			<origin xyz="0 0 0" rpy="0 0 0" />
			<geometry>
				<!-- <box size="0.078 0.08 0.05" /> -->
				<mesh filename="package://pi_12dof_release_v1/meshes/l_ankle_pitch_link.STL" />
			</geometry>
		</collision>
	</link>
	<joint name="l_ankle_pitch_joint" type="revolute">
		<origin xyz="0 0 -0.14" rpy="0 -0.4 0" />
		<parent link="l_knee_pitch_link" />
		<child link="l_ankle_pitch_link" />
		<axis xyz="0 1 0" />
		<limit lower="-0.5" upper="1.3" effort="21" velocity="21" />
	</joint>
	<link name="l_ankle_roll_link">
		<inertial>
			<origin xyz="-0.02383679 0.00019256 -0.0144649" rpy="0 0 0" />
			<mass value="0.51868476" />
			<inertia ixx="0.0003308" ixy="-2.49E-06" ixz="-0.00018245" iyy="0.00113168" iyz="-1.06E-06" izz="0.00098381" />
		</inertial>
		<visual>
			<origin xyz="0 0 0" rpy="0 0 0" />
			<geometry>
				<mesh filename="package://pi_12dof_release_v1/meshes/l_ankle_roll_link.STL" />
			</geometry>
			<material name="">
				<color rgba="0.75294 0.75294 0.75294 1" />
			</material>
		</visual>
		<collision>
			<origin xyz="0 0 0" rpy="0 0 0" />
			<geometry>
				<mesh filename="package://pi_12dof_release_v1/meshes/l_ankle_roll_link.STL" />
			</geometry>
		</collision>
	</link>
	<joint name="l_ankle_roll_joint" type="revolute">
		<origin xyz="0.07525 0 0" rpy="0 0 0" />
		<parent link="l_ankle_pitch_link" />
		<child link="l_ankle_roll_link" />
		<axis xyz="1 0 0" />
		<limit lower="-0.15" upper="0.15" effort="21" velocity="21" />
	</joint>

<!-- right leg -->
	<link name="r_hip_pitch_link">
		<inertial>
			<origin xyz="0.00089428 -0.05527744 -0.00027276" rpy="0 0 0" />
			<mass value="0.36999771" />
			<inertia ixx="8.307E-05" ixy="2E-07" ixz="-5E-08" iyy="9.81E-05" iyz="-7E-07" izz="0.0001085" />
		</inertial>
		<visual>
			<origin xyz="0 0 0" rpy="0 0 0" />
			<geometry>
				<mesh filename="package://pi_12dof_release_v1/meshes/r_hip_pitch_link.STL" />
			</geometry>
			<material name="">
				<color rgba="0.75294 0.75294 0.75294 1" />
			</material>
		</visual>
		<collision>
			<origin xyz="0 0 0" rpy="0 0 0" />
			<geometry>
				<!-- <box size="0.001 0.001 0.001" /> -->
				<mesh filename="package://pi_12dof_release_v1/meshes/r_hip_pitch_link.STL" />
			</geometry>
		</collision>
	</link>
	<joint name="r_hip_pitch_joint" type="revolute">
		<origin xyz="-5.1979E-05 -0.0233 -0.033" rpy="0 -0.25 0" />
		<parent link="base_link" />
		<child link="r_hip_pitch_link" />
		<axis xyz="0 1 0" />
		<limit lower="-1.25" upper="1.75" effort="21" velocity="21" />
	</joint>
	<link name="r_hip_roll_link">
		<inertial>
			<origin xyz="-0.00180153 0.00025956 -0.0608194" rpy="0 0 0" />
			<mass value="0.38851552" />
			<inertia ixx="0.00027042" ixy="3.9E-07" ixz="3.312E-05" iyy="0.0003342" iyz="8.7E-07" izz="0.00013617" />
		</inertial>
		<visual>
			<origin xyz="0 0 0" rpy="0 0 0" />
			<geometry>
				<mesh filename="package://pi_12dof_release_v1/meshes/r_hip_roll_link.STL" />
			</geometry>
			<material name="">
				<color rgba="0.75294 0.75294 0.75294 1" />
			</material>
		</visual>
		<collision>
			<origin xyz="0 0 0" rpy="0 0 0" />
			<geometry>
				<!-- <box size="0.001 0.001 0.001" /> -->
				<mesh filename="package://pi_12dof_release_v1/meshes/r_hip_roll_link.STL" />
			</geometry>
		</collision>
	</link>
	<joint name="r_hip_roll_joint" type="revolute">
		<origin xyz="0.00025 -0.0568 0" rpy="0 0 0" />
		<parent link="r_hip_pitch_link" />
		<child link="r_hip_roll_link" />
		<axis xyz="1 0 0" />
		<limit lower="-0.5" upper="0.12" effort="21" velocity="21" />
	</joint>
	<link name="r_hip_yaw_link">
		<inertial>
			<origin xyz="0 0.00116854 -0.04755896" rpy="0 0 0" />
			<mass value="0.11270879" />
			<inertia ixx="0.00012496" ixy="0" ixz="0" iyy="5.82E-05" iyz="3.19E-06" izz="9.438E-05" />
		</inertial>
		<visual>
			<origin xyz="0 0 0" rpy="0 0 0" />
			<geometry>
				<mesh filename="package://pi_12dof_release_v1/meshes/r_thigh_link.STL" />
			</geometry>
			<material name="">
				<color rgba="0.75294 0.75294 0.75294 1" />
			</material>
		</visual>
		<collision>
			<origin xyz="0 0 0" rpy="0 0 0" />
			<geometry>
				<!-- <box size="0.001 0.001 0.001" /> -->
				<mesh filename="package://pi_12dof_release_v1/meshes/r_thigh_link.STL" />
			</geometry>
		</collision>
	</link>
	<joint name="r_hip_yaw_joint" type="revolute">
		<origin xyz="-0.00025 0 -0.06925" rpy="0 0 0" />
		<parent link="r_hip_roll_link" />
		<child link="r_hip_yaw_link" />
		<axis xyz="0 0 1" />
		<limit lower="-0.6" upper="0.3" effort="21" velocity="21" />
	</joint>
	<link name="r_knee_pitch_link">
		<inertial>
			<origin xyz="-0.00026627 -0.00116537 -0.06971210" rpy="0 0 0" />
			<mass value="0.81374212" />
			<inertia ixx="0.00352123" ixy="0.00000020" ixz="-0.00000072" iyy="0.00349946" iyz="-0.00002072" izz="0.00017468" />
		</inertial>
		<visual>
			<origin xyz="0 0 0" rpy="0 0 0" />
			<geometry>
				<mesh filename="package://pi_12dof_release_v1/meshes/r_calf_link.STL" />
			</geometry>
			<material name="">
				<color rgba="0.75294 0.75294 0.75294 1" />
			</material>
		</visual>
		<collision>
			<origin xyz="0 0 0" rpy="0 0 0" />
			<geometry>
				<!-- <box size="0.001 0.001 0.001" /> -->
				<mesh filename="package://pi_12dof_release_v1/meshes/r_calf_link.STL" />
			</geometry>
		</collision>
	</link>
	<joint name="r_knee_pitch_joint" type="revolute">
		<origin xyz="0 -0.0027 -0.07025" rpy="0 0.65 0" />
		<parent link="r_hip_yaw_link" />
		<child link="r_knee_pitch_link" />
		<axis xyz="0 1 0" />
		<limit lower="-0.65" upper="1.65" effort="21" velocity="21" />
	</joint>
	<link name="r_ankle_pitch_link">
		<inertial>
			<origin xyz="0.00467932 0.00347699 0" rpy="0 0 0" />
			<mass value="0.1759244" />
			<inertia ixx="0.00011981" ixy="6.4E-07" ixz="0" iyy="0.00022179" iyz="0" izz="0.00030766" />
		</inertial>
		<visual>
			<origin xyz="0 0 0" rpy="0 0 0" />
			<geometry>
				<mesh filename="package://pi_12dof_release_v1/meshes/r_ankle_pitch_link.STL" />
			</geometry>
			<material name="">
				<color rgba="0.75294 0.75294 0.75294 1" />
			</material>
		</visual>
		<collision>
			<origin xyz="0 0 0" rpy="0 0 0" />
			<geometry>
				<!-- <box size="0.078 0.08 0.05" /> -->
				<mesh filename="package://pi_12dof_release_v1/meshes/r_ankle_pitch_link.STL" />
			</geometry>
		</collision>
	</link>
	<joint name="r_ankle_pitch_joint" type="revolute">
		<origin xyz="0 0 -0.14" rpy="0 -0.4 0" />
		<parent link="r_knee_pitch_link" />
		<child link="r_ankle_pitch_link" />
		<axis xyz="0 1 0" />
		<limit lower="-0.5" upper="1.3" effort="21" velocity="21" />
	</joint>
	<link name="r_ankle_roll_link">
		<inertial>
			<origin xyz="-0.02383679 0.00019256 -0.0144649" rpy="0 0 0" />
			<mass value="0.51868476" />
			<inertia ixx="0.0003308" ixy="-2.49E-06" ixz="-0.00018245" iyy="0.00113168" iyz="-1.06E-06" izz="0.00098381" />
		</inertial>
		<visual>
			<origin xyz="0 0 0" rpy="0 0 0" />
			<geometry>
				<mesh filename="package://pi_12dof_release_v1/meshes/r_ankle_roll_link.STL" />
			</geometry>
			<material name="">
				<color rgba="0.75294 0.75294 0.75294 1" />
			</material>
		</visual>
		<collision>
			<origin xyz="0 0 0" rpy="0 0 0" />
			<geometry>
				<mesh filename="package://pi_12dof_release_v1/meshes/r_ankle_roll_link.STL" />
			</geometry>
		</collision>
	</link>
	<joint name="r_ankle_roll_joint" type="revolute">
		<origin xyz="0.07525 0.0027 0" rpy="0 0 0" />
		<parent link="r_ankle_pitch_link" />
		<child link="r_ankle_roll_link" />
		<axis xyz="1 0 0" />
		<limit lower="-0.15" upper="0.15" effort="21" velocity="21" />
	</joint>

<!-- Left Leg -->
	<transmission name="l_hip_pitch_trans">
    	<type>transmission_interface/SimpleTransmission</type>
    	<joint name="l_hip_pitch_joint">
      		<hardwareInterface>hardware_interface/EffortJointInterface</hardwareInterface>
    	</joint>
    	<actuator name="l_hip_pitch_motor">
      		<mechanicalReduction>1.0</mechanicalReduction>
      		<hardwareInterface>hardware_interface/EffortJointInterface</hardwareInterface>
    	</actuator>
  	</transmission>

	<transmission name="l_hip_roll_trans">
    	<type>transmission_interface/SimpleTransmission</type>
    	<joint name="l_hip_roll_joint">
      		<hardwareInterface>hardware_interface/EffortJointInterface</hardwareInterface>
    	</joint>
    	<actuator name="l_hip_roll_motor">
      		<mechanicalReduction>1.0</mechanicalReduction>
      		<hardwareInterface>hardware_interface/EffortJointInterface</hardwareInterface>
    	</actuator>
  	</transmission>

	<transmission name="l_hip_yaw_trans">
    	<type>transmission_interface/SimpleTransmission</type>
    	<joint name="l_hip_yaw_joint">
      		<hardwareInterface>hardware_interface/EffortJointInterface</hardwareInterface>
    	</joint>
    	<actuator name="l_hip_yaw_motor">
      		<mechanicalReduction>1.0</mechanicalReduction>
      		<hardwareInterface>hardware_interface/EffortJointInterface</hardwareInterface>
    	</actuator>
  	</transmission>

	<transmission name="l_knee_pitch_trans">
    	<type>transmission_interface/SimpleTransmission</type>
    	<joint name="l_knee_pitch_joint">
      		<hardwareInterface>hardware_interface/EffortJointInterface</hardwareInterface>
    	</joint>
    	<actuator name="l_knee_pitch_motor">
      		<mechanicalReduction>1.0</mechanicalReduction>
      		<hardwareInterface>hardware_interface/EffortJointInterface</hardwareInterface>
    	</actuator>
  	</transmission>

	<transmission name="l_ankle_pitch_trans">
    	<type>transmission_interface/SimpleTransmission</type>
    	<joint name="l_ankle_pitch_joint">
      		<hardwareInterface>hardware_interface/EffortJointInterface</hardwareInterface>
    	</joint>
    	<actuator name="l_ankle_pitch_motor">
      		<mechanicalReduction>1.0</mechanicalReduction>
      		<hardwareInterface>hardware_interface/EffortJointInterface</hardwareInterface>
    	</actuator>
  	</transmission>

	<transmission name="l_ankle_roll_trans">
    	<type>transmission_interface/SimpleTransmission</type>
    	<joint name="l_ankle_roll_joint">
      		<hardwareInterface>hardware_interface/EffortJointInterface</hardwareInterface>
    	</joint>
    	<actuator name="l_ankle_roll_motor">
      		<mechanicalReduction>1.0</mechanicalReduction>
      		<hardwareInterface>hardware_interface/EffortJointInterface</hardwareInterface>
    	</actuator>
  	</transmission>

<!-- Right Leg -->
	<transmission name="r_hip_pitch_trans">
    	<type>transmission_interface/SimpleTransmission</type>
    	<joint name="r_hip_pitch_joint">
      		<hardwareInterface>hardware_interface/EffortJointInterface</hardwareInterface>
    	</joint>
    	<actuator name="r_hip_pitch_motor">
      		<mechanicalReduction>1.0</mechanicalReduction>
      		<hardwareInterface>hardware_interface/EffortJointInterface</hardwareInterface>
    	</actuator>
  	</transmission>

	<transmission name="r_hip_roll_trans">
    	<type>transmission_interface/SimpleTransmission</type>
    	<joint name="r_hip_roll_joint">
      		<hardwareInterface>hardware_interface/EffortJointInterface</hardwareInterface>
    	</joint>
    	<actuator name="r_hip_roll_motor">
      		<mechanicalReduction>1.0</mechanicalReduction>
      		<hardwareInterface>hardware_interface/EffortJointInterface</hardwareInterface>
    	</actuator>
  	</transmission>

	<transmission name="r_hip_yaw_trans">
    	<type>transmission_interface/SimpleTransmission</type>
    	<joint name="r_hip_yaw_joint">
      		<hardwareInterface>hardware_interface/EffortJointInterface</hardwareInterface>
    	</joint>
    	<actuator name="r_hip_yaw_motor">
      		<mechanicalReduction>1.0</mechanicalReduction>
      		<hardwareInterface>hardware_interface/EffortJointInterface</hardwareInterface>
    	</actuator>
  	</transmission>

	<transmission name="r_knee_pitch_trans">
    	<type>transmission_interface/SimpleTransmission</type>
    	<joint name="r_knee_pitch_joint">
      		<hardwareInterface>hardware_interface/EffortJointInterface</hardwareInterface>
    	</joint>
    	<actuator name="r_knee_pitch_motor">
      		<mechanicalReduction>1.0</mechanicalReduction>
      		<hardwareInterface>hardware_interface/EffortJointInterface</hardwareInterface>
    	</actuator>
  	</transmission>

	<transmission name="r_ankle_pitch_trans">
    	<type>transmission_interface/SimpleTransmission</type>
    	<joint name="r_ankle_pitch_joint">
      		<hardwareInterface>hardware_interface/EffortJointInterface</hardwareInterface>
    	</joint>
    	<actuator name="r_ankle_pitch_motor">
      		<mechanicalReduction>1.0</mechanicalReduction>
      		<hardwareInterface>hardware_interface/EffortJointInterface</hardwareInterface>
    	</actuator>
  	</transmission>

	<transmission name="r_ankle_roll_trans">
    	<type>transmission_interface/SimpleTransmission</type>
    	<joint name="r_ankle_roll_joint">
      		<hardwareInterface>hardware_interface/EffortJointInterface</hardwareInterface>
    	</joint>
    	<actuator name="r_ankle_roll_motor">
      		<mechanicalReduction>1.0</mechanicalReduction>
      		<hardwareInterface>hardware_interface/EffortJointInterface</hardwareInterface>
    	</actuator>
  	</transmission>

	<!-- 控制插件载入 -->
	<gazebo>
		<plugin name="gazebo_ros_control" filename="libhit_robot_hw_sim.so">
			<robotNamespace>/</robotNamespace> <!-- 读取参数服务器参数名称的前缀 -->
			<robotParam>robot_description</robotParam>
			<robotSimType>hit_robot_hw/HitRobotHWSim</robotSimType>
		</plugin>
	</gazebo>

<!-- left -->
	<gazebo reference="l_ankle_roll_link">
		<kp>100000.0</kp>
		<kd>1000</kd>
		<mu1>1</mu1>
		<mu2>1</mu2>
		<self_collide>0</self_collide>
		<!-- <maxContacts>30</maxContacts> -->
		<!-- <minDepth>0.001</minDepth> -->
		<!-- <fdir1>1 0 0</fdir1> -->
	</gazebo>

	<gazebo reference="l_ankle_pitch_link">
		<kp>100000.0</kp>
		<kd>1000</kd>
		<mu1>10</mu1>
		<mu2>10</mu2>
		<self_collide>0</self_collide>
		<!-- <maxContacts>30</maxContacts> -->
		<!-- <minDepth>0.001</minDepth> -->
		<!-- <fdir1>1 0 0</fdir1> -->
	</gazebo>

	<gazebo reference="l_knee_pitch_link">
		<kp>100000.0</kp>
		<kd>1000</kd>
		<mu1>1</mu1>
		<mu2>1</mu2>
		<self_collide>0</self_collide>
		<!-- <maxContacts>30</maxContacts> -->
		<!-- <minDepth>0.001</minDepth> -->
		<!-- <fdir1>1 0 0</fdir1> -->
	</gazebo>

	<gazebo reference="l_hip_yaw_link">
		<kp>100000.0</kp>
		<kd>1000</kd>
		<mu1>1</mu1>
		<mu2>1</mu2>
		<self_collide>0</self_collide>
		<!-- <maxContacts>30</maxContacts> -->
		<!-- <minDepth>0.001</minDepth> -->
		<!-- <fdir1>1 0 0</fdir1> -->
	</gazebo>

	<gazebo reference="l_hip_roll_link">
		<kp>100000.0</kp>
		<kd>1000</kd>
		<mu1>1</mu1>
		<mu2>1</mu2>
		<self_collide>0</self_collide>
		<!-- <maxContacts>30</maxContacts> -->
		<!-- <minDepth>0.001</minDepth> -->
		<!-- <fdir1>1 0 0</fdir1> -->
	</gazebo>

	<gazebo reference="l_hip_pitch_link">
		<kp>100000.0</kp>
		<kd>1000</kd>
		<mu1>1</mu1>
		<mu2>1</mu2>
		<self_collide>0</self_collide>
		<!-- <maxContacts>30</maxContacts> -->
		<!-- <minDepth>0.001</minDepth> -->
		<!-- <fdir1>1 0 0</fdir1> -->
	</gazebo>

<!-- left -->
	<gazebo reference="r_ankle_roll_link">
		<kp>100000.0</kp>
		<kd>1000</kd>
		<mu1>10</mu1>
		<mu2>10</mu2>
		<self_collide>0</self_collide>
		<!-- <maxContacts>30</maxContacts> -->
		<!-- <minDepth>0.001</minDepth> -->
		<!-- <fdir1>1 0 0</fdir1> -->
	</gazebo>

	<gazebo reference="r_ankle_pitch_link">
		<kp>100000.0</kp>
		<kd>1000</kd>
		<mu1>1</mu1>
		<mu2>1</mu2>
		<self_collide>0</self_collide>
		<!-- <maxContacts>30</maxContacts> -->
		<!-- <minDepth>0.001</minDepth> -->
		<!-- <fdir1>1 0 0</fdir1> -->
	</gazebo>

	<gazebo reference="r_knee_pitch_link">
		<kp>100000.0</kp>
		<kd>1000</kd>
		<mu1>1</mu1>
		<mu2>1</mu2>
		<self_collide>0</self_collide>
		<!-- <maxContacts>30</maxContacts> -->
		<!-- <minDepth>0.001</minDepth> -->
		<!-- <fdir1>1 0 0</fdir1> -->
	</gazebo>

	<gazebo reference="r_hip_yaw_link">
		<kp>100000.0</kp>
		<kd>1000</kd>
		<mu1>1</mu1>
		<mu2>1</mu2>
		<self_collide>0</self_collide>
		<!-- <maxContacts>30</maxContacts> -->
		<!-- <minDepth>0.001</minDepth> -->
		<!-- <fdir1>1 0 0</fdir1> -->
	</gazebo>

	<gazebo reference="r_hip_roll_link">
		<kp>100000.0</kp>
		<kd>1000</kd>
		<mu1>1</mu1>
		<mu2>1</mu2>
		<self_collide>0</self_collide>
		<!-- <maxContacts>30</maxContacts> -->
		<!-- <minDepth>0.001</minDepth> -->
		<!-- <fdir1>1 0 0</fdir1> -->
	</gazebo>

	<gazebo reference="r_hip_pitch_link">
		<kp>100000.0</kp>
		<kd>1000</kd>
		<mu1>1</mu1>
		<mu2>1</mu2>
		<self_collide>0</self_collide>
		<!-- <maxContacts>30</maxContacts> -->
		<!-- <minDepth>0.001</minDepth> -->
		<!-- <fdir1>1 0 0</fdir1> -->
	</gazebo>

</robot>